Workbook
Name Должность: [1]Должность!$F$1:$F$14
Name Ф.И.О.: '[1]Ф.И.О.'!$B$4:$B$63

Sheet сборка  узлов исходник Голубев
B1: ООО "ПК "Техинком-Центр"
D3: Наряд на оплату труда №
D4: сборка-сварка узлов
A5: Изделие :_____АЦ-6-40 ш. Камаз 43118 с_________начать производство продукции
B8: Продукция: ПСС 131. 18Э/22Э | D8: =A8:D32 -> 0
B9: Подразделение: высотная техника
B10: Заводской номер:
B11: Общий фонд по машине:
B12: Фактически выплаченный фонд з/п, нарастающим итогом
A15: № п /п | B15: Наименование операции | C15: Расценка (руб.) | D15: норм/час
A16: 1 | B16: Рама опорная 1 шт. | C16: 41996 | D16: 108
B17: Аутригера 4 шт. | C17: 27000 | D17: 60
B18: Элементы | C18: 36414 | D18: 90
B19: Поворотная колонна 1 шт. | C19: 20800 | D19: 52
B20: Колено 1 короб 1 шт | C20: 6400 | D20: 16
B21: Колено 2 короб 1 шт. | C21: 6400 | D21: 16
B22: Колено 3 короб 1 шт. | C22: 6400 | D22: 16
B23: Колено 4 короб 1 шт. | C23: 6400 | D23: 16
B24: Колено 1 обвязка 1 шт. | C24: 6400 | D24: 16
B25: Колено 2 обвязка 1 шт. | C25: 6400 | D25: 16
B26: Колено 3 обвязка 1шт. | C26: 6400 | D26: 16
B27: Колено 4 обвязка 1 шт. | C27: 6400 | D27: 16
B28: Перекатное 2 шт. | C28: 2856 | D28: 8
B29: Кронштейны люльки 2 шт. | C29: 8000 | D29: 20
C48: =SUM(C16:C47) -> 188266 | D48: =SUM(D16:D47) -> 466

Sheet сборка машишы исходник Голубева
B1: ООО "ПК "Техинком-Центр"
D3: Наряд на оплату труда №
D4: сборка машины
A5: Изделие :_____АЦ-6-40 ш. Камаз 43118 с_________начать производство продукции
B8: Продукция: ПСС 131. 18Э/22Э
B9: Подразделение: высотная техника
B10: Заводской номер:
B11: Общий фонд по машине:
B12: Фактически выплаченный фонд з/п, нарастающим итогом
A15: № п /п | B15: Наименование операции | C15: Расценка (руб.) | D15: норм/час
A16: 1 | B16: Доработка шасси 1 шт | C16: 8656 | D16: 24
A17: 2 | B17: маслобак (проверка,сборка,установка) | C17: 3678 | D17: 10
A18: 3 | B18: Установка рамы опорной, стойки 1 шт. | C18: 6550 | D18: 18
A19: 4 | B19: Сборка- установка аутригеров 4 шт. | C19: 11600 | D19: 32
A20: 5 | B20: Сборка пульта оператора 1 шт. | C20: 3000 | D20: 8
A21: 6 | B21: установка элементов | C21: 17964 | D21: 48
A22: 7 | B22: сборка-установка колонны, ОПУ.пульта опер. | C22: 11700 | D22: 28
A23: 8 | B23: сборка-установка стрелы | C23: 30000 | D23: 80
A24: 9 | B24: сборка-установка рабочей платформы | C24: 13500 | D24: 30
A25: 10 | B25: гидравлика | C25: 27000 | D25: 60
A26: 11 | B26: электрика | C26: 38700 | D26: 86
A27: 12 | B27: Наладка, испытания, сдача ОТК 1 маш. | C27: 32200 | D27: 66
A28: 0
C48: =SUM(C16:C47) -> 204548 | D48: =SUM(D16:D47) -> 490

Sheet январь
B1: ООО "ПК "Техинком-Центр"
A3: Наряд на оплату труда №_____ от "___" _______________20___г.
F4: Изделие : | H4: =C6 -> ПСС-131.22Э (С42А43) 58Е-ТВ Садко НЕКСТ
B6: Продукция: | C6: ПСС-131.22Э (С42А43) 58Е-ТВ Садко НЕКСТ
B7: Подразделение: высотная техника
B8: Заводской номер: | C8: №011
B9: Количество: | F9: 1 | G9: шт.
B10: Общий фонд по машине | F10: =E177 -> 558558 | G10: руб.
B11: Трудоемкость | F11: =F177 -> 1302 | G11: н/час
B12: Стоимость н/ч (руб) | F12: =E177/F177 -> 429 | G12: руб.
A14: № | B14: Наименование операции | C14: % выполнения операции на начало месяца | D14: Справочно % от суммы наряда | E14: Утвержденные расценки и н/ч | G14: Факт выполнения нарастающим итогом на 01.01.2024г. | I14: Факт выполнения за ЯНВАРЬ 2024г. | K14: Исполнитель (ФИО) | N14: Отработано на 31.01.2024г. | P14: % выполнения операции на конец месяца | Q14: Остаток на конец месяца н/ч | R14: Отклонение на конец месяца
A15: п/п | E15: расценка за операцию (руб.) | F15: нормо- час (н/ч) | G15: (руб.) | H15: (н/ч) | I15: Стоимость (руб.) | J15: факт выполнения (н/ч) | K15: з/плата (сделка) | L15: договор ГПХ | M15: подряд | N15: сумма (руб.) | O15: н/ч. | R15: % | S15: рубли
A16: 1 | B16: Сварка-сборка узлов | C16: =H16/F16 -> 0 | D16: =E16/E$177 -> 0.59600614 | E16: =SUM(E23:E92) -> 332904 | F16: =SUM(F23:F92) -> 776 | G16: =SUM(G23:G92) -> 0 | H16: =SUM(H23:H92) -> 0 | I16: =SUM(I23:I92) -> 0 | J16: =SUM(J23:J92) -> 0 | N16: =G16+SUM(I16:I22) -> 0 | O16: =H16+SUM(J16:J22) -> 0 | P16: =O16/F16 -> 0 | Q16: =F16-O16 -> 776 | R16: =1-N16/E16 -> 1 | S16: =E16-N16 -> 332904
A23: 1.1. | B23: Рама опорная 58Е-ТВ.40.00.00-02: 58Е-ТВ.40.01.00 Балка/58Е-ТВ.40.01.00-01 Балка 58Е-ТВ.40.02.00 Балка задних опор 58Е-ТВ.40.03.00-01 Опора 58Б-ТВ.40.12.00 Кронштейн 58Г-ТВ.40.00.40 Кронштейн ручного насоса 58Б-ТВ.00.10.00 Кронштейн 58Б-ТВ.40.12.00 Кронштейн 58Д-ТВ.40.02.10 Кронштейн/58Д-ТВ.40.02.10-01 Кронштейн | C23: =H23/F23 -> 0 | E23: =F23*429 -> 46332 | F23: 108 | I23: =E23/F23*J23 -> 0 | N23: =G23+SUM(I23:I29) -> 0 | O23: =H23+SUM(J23:J29) -> 0 | P23: =O23/F23 -> 0 | Q23: =F23-O23 -> 108 | R23: =1-N23/E23 -> 1 | S23: =E23-N23 -> 46332
I24: =E23/F23*J24 -> 0
I25: =E23/F23*J25 -> 0
I26: =E23/F23*J26 -> 0
I27: =E23/F23*J27 -> 0
I28: =E23/F23*J28 -> 0
I29: =E23/F23*J29 -> 0
A30: 1.2. | B30: Аутригеры 58Е-ТВ.42.00.00: 58Е-ТВ.40.06.00 Кронштейн 58Е-ТВ.40.08.00 Опора 58Е-ТВ.42.01.00 Балка передняя 58Е-ТВ.42.02.00 Балка задняя 58Е-ТВ.40.05.00 Кронштейн | C30: =H30/F30 -> 0 | E30: =F30*429 -> 41184 | F30: 96 | I30: =E30/F30*J30 -> 0 | N30: =G30+SUM(I30:I36) -> 0 | O30: =H30+SUM(J30:J36) -> 0 | P30: =O30/F30 -> 0 | Q30: =F30-O30 -> 96 | R30: =1-N30/E30 -> 1 | S30: =E30-N30 -> 41184
I31: =E30/F30*J31 -> 0
I32: =E30/F30*J32 -> 0
I33: =E30/F30*J33 -> 0
I34: =E30/F30*J34 -> 0
I35: =E30/F30*J35 -> 0
I36: =E30/F30*J36 -> 0
A37: 1.3. | B37: Элементы: /Пульт оператора 58Е-ТВ.10.20.00, /Бампер 58Е-ТВ.28.110.00 /Ящики задние 58Е-ТВ.28.10.00_58Е-ТВ.28.20.00 /площадка оператора 58Е-ТВ.10.25.00 /кронштейн сидения оператора 58Е-ТВ.28.30.10 /крылья 58Е-ТВ.01.50.00 /колпаки 58Е-ТВ.10.100.00 /стойка 58Е-ТВ.28.40.00 /маслобак 58А-ТВ.12.10.00 /кронштейн транспортного положения стрелы 58Е-ТВ.50.40.74-84 (6 поз.) /кронштейны под элементы гидравлики в поворотной колонне, раме, /Лестница 58Е-ТВ.28.70.00 (боковые ступени) | C37: =H37/F37 -> 0 | E37: =F37*429 -> 71214 | F37: 166 | I37: =E37/F37*J37 -> 0 | N37: =G37+SUM(I37:I43) -> 0 | O37: =H37+SUM(J37:J43) -> 0 | P37: =O37/F37 -> 0 | Q37: =F37-O37 -> 166 | R37: =1-N37/E37 -> 1 | S37: =E37-N37 -> 71214
I38: =E37/F37*J38 -> 0
I39: =E37/F37*J39 -> 0
I40: =E37/F37*J40 -> 0
I41: =E37/F37*J41 -> 0
I42: =E37/F37*J42 -> 0
I43: =E37/F37*J43 -> 0
A44: 1.4. | B44: Поворотная колонна 58Е-ТВ.46.01.00: 58Д-ТВ.45.10.20 Кронштейн 58Е-ТВ.46.01.10 Балка 58Е-ТВ.46.10.10 Боковина правая 58Е-ТВ.46.10.10-01 Боковина левая | C44: =H44/F44 -> 0 | D44: =E44/E$177 -> 0.052227343 | E44: =F44*429 -> 29172 | F44: 68 | I44: =E44/F44*J44 -> 0 | N44: =G44+SUM(I44:I50) -> 0 | O44: =H44+SUM(J44:J50) -> 0 | P44: =O44/F44 -> 0 | Q44: =F44-O44 -> 68 | R44: =1-N44/E44 -> 1 | S44: =E44-N44 -> 29172
I45: =E44/F44*J45 -> 0
I46: =E44/F44*J46 -> 0
I47: =E44/F44*J47 -> 0
I48: =E44/F44*J48 -> 0
I49: =E44/F44*J49 -> 0
...

Sheet февраль
B1: ООО "ПК "Техинком-Центр"
A3: Наряд на оплату труда №_____ от "___" _______________20___г.
F4: Изделие : | H4: =C6 -> ПСС-131.22Э (С42А43) 58Е-ТВ Садко НЕКСТ
B6: Продукция: | C6: =январь!C6 -> ПСС-131.22Э (С42А43) 58Е-ТВ Садко НЕКСТ
B7: Подразделение: высотная техника
B8: Заводской номер: | C8: =январь!C8 -> №011
B9: Количество: | F9: 1 | G9: шт.
B10: Общий фонд по машине | F10: =E177 -> 558558 | G10: руб.
B11: Трудоемкость | F11: =F177 -> 1302 | G11: н/час
B12: Стоимость н/ч (руб) | F12: =E177/F177 -> 429 | G12: руб.
A14: № | B14: Наименование операции | C14: % выполнения операции на начало месяца | D14: Справочно % от суммы наряда | E14: Утвержденные расценки и н/ч | G14: Факт выполнения нарастающим итогом на 01.02.2024г. | I14: Факт выполнения за ФЕВРАЛЬ 2024г. | K14: Исполнитель (ФИО) | N14: Отработано на 29.02.2024г. | P14: % выполнения операции на конец месяца | Q14: Остаток на конец месяца н/ч | R14: Отклонение на конец месяца
A15: п/п | E15: расценка за операцию (руб.) | F15: нормо-час (н/ч) | G15: (руб.) | H15: (н/ч) | I15: Стоимость (руб.) | J15: факт выполнения (н/ч) | K15: з/плата (сделка) | L15: договор ГПХ | M15: подряд | N15: сумма (руб.) | O15: н/ч. | R15: % | S15: рубли
A16: 1 | B16: Сварка-сборка узлов | C16: =H16/F16 -> 0 | D16: =E16/E$177 -> 0.59600614 | E16: =SUM(E23:E92) -> 332904 | F16: =SUM(F23:F92) -> 776 | G16: =SUM(G23:G92) -> 0 | H16: =SUM(H23:H92) -> 0 | I16: =SUM(I23:I92) -> 0 | J16: =SUM(J23:J92) -> 0 | N16: =SUM(N23:N92) -> 0 | O16: =SUM(O23:O92) -> 0 | P16: =O16/F16 -> 0 | Q16: =F16-O16 -> 776 | R16: =1-N16/E16 -> 1 | S16: =E16-N16 -> 332904
A23: 1.1. | B23: Рама опорная 58Е-ТВ.40.00.00-02: 58Е-ТВ.40.01.00 Балка/58Е-ТВ.40.01.00-01 Балка 58Е-ТВ.40.02.00 Балка задних опор 58Е-ТВ.40.03.00-01 Опора 58Б-ТВ.40.12.00 Кронштейн 58Г-ТВ.40.00.40 Кронштейн ручного насоса 58Б-ТВ.00.10.00 Кронштейн 58Б-ТВ.40.12.00 Кронштейн 58Д-ТВ.40.02.10 Кронштейн/58Д-ТВ.40.02.10-01 Кронштейн | C23: =H23/F23 -> 0 | E23: =F23*429 -> 46332 | F23: 108 | G23: =январь!N23:N29 -> 0 | H23: =январь!O23:O29 -> 0 | I23: =E23/F23*J23 -> 0 | N23: =G23+SUM(I23:I29) -> 0 | O23: =H23+SUM(J23:J29) -> 0 | P23: =O23/F23 -> 0 | Q23: =F23-O23 -> 108 | R23: =1-N23/E23 -> 1 | S23: =E23-N23 -> 46332
I24: =E23/F23*J24 -> 0
I25: =E23/F23*J25 -> 0
I26: =E23/F23*J26 -> 0
I27: =E23/F23*J27 -> 0
I28: =E23/F23*J28 -> 0
I29: =E23/F23*J29 -> 0
A30: 1.2. | B30: Аутригеры 58Е-ТВ.42.00.00: 58Е-ТВ.40.06.00 Кронштейн 58Е-ТВ.40.08.00 Опора 58Е-ТВ.42.01.00 Балка передняя 58Е-ТВ.42.02.00 Балка задняя 58Е-ТВ.40.05.00 Кронштейн | C30: =H30/F30 -> 0 | E30: =F30*429 -> 41184 | F30: 96 | G30: =январь!N30:N36 -> 0 | H30: =январь!O30:O36 -> 0 | I30: =E30/F30*J30 -> 0 | N30: =G30+SUM(I30:I36) -> 0 | O30: =H30+SUM(J30:J36) -> 0 | P30: =O30/F30 -> 0 | Q30: =F30-O30 -> 96 | R30: =1-N30/E30 -> 1 | S30: =E30-N30 -> 41184
I31: =E30/F30*J31 -> 0
I32: =E30/F30*J32 -> 0
I33: =E30/F30*J33 -> 0
I34: =E30/F30*J34 -> 0
I35: =E30/F30*J35 -> 0
I36: =E30/F30*J36 -> 0
A37: 1.3. | B37: Элементы: /Пульт оператора 58Е-ТВ.10.20.00, /Бампер 58Е-ТВ.28.110.00 /Ящики задние 58Е-ТВ.28.10.00_58Е-ТВ.28.20.00 /площадка оператора 58Е-ТВ.10.25.00 /кронштейн сидения оператора 58Е-ТВ.28.30.10 /крылья 58Е-ТВ.01.50.00 /колпаки 58Е-ТВ.10.100.00 /стойка 58Е-ТВ.28.40.00 /маслобак 58А-ТВ.12.10.00 /кронштейн транспортного положения стрелы 58Е-ТВ.50.40.74-84 (6 поз.) /кронштейны под элементы гидравлики в поворотной колонне, раме, /Лестница 58Е-ТВ.28.70.00 (боковые ступени) | C37: =H37/F37 -> 0 | E37: =F37*429 -> 71214 | F37: 166 | G37: =январь!N37:N43 -> 0 | H37: =январь!O37:O43 -> 0 | I37: =E37/F37*J37 -> 0 | N37: =G37+SUM(I37:I43) -> 0 | O37: =H37+SUM(J37:J43) -> 0 | P37: =O37/F37 -> 0 | Q37: =F37-O37 -> 166 | R37: =1-N37/E37 -> 1 | S37: =E37-N37 -> 71214
I38: =E37/F37*J38 -> 0
I39: =E37/F37*J39 -> 0
I40: =E37/F37*J40 -> 0
I41: =E37/F37*J41 -> 0
I42: =E37/F37*J42 -> 0
I43: =E37/F37*J43 -> 0
A44: 1.4. | B44: Поворотная колонна 58Е-ТВ.46.01.00: 58Д-ТВ.45.10.20 Кронштейн 58Е-ТВ.46.01.10 Балка 58Е-ТВ.46.10.10 Боковина правая 58Е-ТВ.46.10.10-01 Боковина левая | C44: =H44/F44 -> 0 | D44: =E44/E$177 -> 0.052227343 | E44: =F44*429 -> 29172 | F44: 68 | G44: =январь!N44:N50 -> 0 | H44: =январь!O44:O50 -> 0 | I44: =E44/F44*J44 -> 0 | N44: =G44+SUM(I44:I50) -> 0 | O44: =H44+SUM(J44:J50) -> 0 | P44: =O44/F44 -> 0 | Q44: =F44-O44 -> 68 | R44: =1-N44/E44 -> 1 | S44: =E44-N44 -> 29172
I45: =E44/F44*J45 -> 0
I46: =E44/F44*J46 -> 0
I47: =E44/F44*J47 -> 0
I48: =E44/F44*J48 -> 0
I49: =E44/F44*J49 -> 0
...

Sheet март
B1: ООО "ПК "Техинком-Центр"
A3: Наряд на оплату труда №_____ от "___" _______________20___г.
F4: Изделие : | H4: =C6 -> ПСС-131.22Э (С42А43) 58Е-ТВ Садко НЕКСТ
B6: Продукция: | C6: =февраль!C6 -> ПСС-131.22Э (С42А43) 58Е-ТВ Садко НЕКСТ
B7: Подразделение: высотная техника
B8: Заводской номер: | C8: =февраль!C8 -> №011
B9: Количество: | F9: 1 | G9: шт.
B10: Общий фонд по машине | F10: =E177 -> 558558 | G10: руб.
B11: Трудоемкость | F11: =F177 -> 1302 | G11: н/час
B12: Стоимость н/ч (руб) | F12: =E177/F177 -> 429 | G12: руб.
A14: № | B14: Наименование операции | C14: % выполнения операции на начало месяца | D14: Справочно % от суммы наряда | E14: Утвержденные расценки и н/ч | G14: Факт выполнения нарастающим итогом на 01.03.2024 | I14: Факт выполнения за МАРТ 2024 | K14: Исполнитель (ФИО) | N14: Отработано на 31.03.2024 | P14: % выполнения операции на конец месяца | Q14: Остаток на конец месяца н/ч | R14: Отклонение на конец месяца
A15: п/п | E15: расценка за операцию (руб.) | F15: нормо-час (н/ч) | G15: (руб.) | H15: (н/ч) | I15: Стоимость (руб.) | J15: факт выполнения (н/ч) | K15: з/плата (сделка) | L15: договор ГПХ | M15: подряд | N15: сумма (руб.) | O15: н/ч. | R15: % | S15: рубли
A16: 1 | B16: Сварка-сборка узлов | C16: =H16/F16 -> 0 | D16: =E16/E$177 -> 0.59600614 | E16: =SUM(E23:E92) -> 332904 | F16: =SUM(F23:F92) -> 776 | G16: =SUM(G23:G92) -> 0 | H16: =SUM(H23:H92) -> 0 | I16: =SUM(I23:I92) -> 0 | J16: =SUM(J23:J92) -> 0 | N16: =SUM(N23:N92) -> 0 | O16: =SUM(O23:O92) -> 0 | P16: =O16/F16 -> 0 | Q16: =F16-O16 -> 776 | R16: =1-N16/E16 -> 1 | S16: =E16-N16 -> 332904
A23: 1.1. | B23: Рама опорная 58Е-ТВ.40.00.00-02: 58Е-ТВ.40.01.00 Балка/58Е-ТВ.40.01.00-01 Балка 58Е-ТВ.40.02.00 Балка задних опор 58Е-ТВ.40.03.00-01 Опора 58Б-ТВ.40.12.00 Кронштейн 58Г-ТВ.40.00.40 Кронштейн ручного насоса 58Б-ТВ.00.10.00 Кронштейн 58Б-ТВ.40.12.00 Кронштейн 58Д-ТВ.40.02.10 Кронштейн/58Д-ТВ.40.02.10-01 Кронштейн | C23: =H23/F23 -> 0 | E23: =F23*429 -> 46332 | F23: 108 | G23: =февраль!N23:N29 -> 0 | H23: =февраль!O23:O29 -> 0 | I23: =E23/F23*J23 -> 0 | N23: =G23+SUM(I23:I29) -> 0 | O23: =H23+SUM(J23:J29) -> 0 | P23: =O23/F23 -> 0 | Q23: =F23-O23 -> 108 | R23: =1-N23/E23 -> 1 | S23: =E23-N23 -> 46332
I24: =E23/F23*J24 -> 0
I25: =E23/F23*J25 -> 0
I26: =E23/F23*J26 -> 0
I27: =E23/F23*J27 -> 0
I28: =E23/F23*J28 -> 0
I29: =E23/F23*J29 -> 0
A30: 1.2. | B30: Аутригеры 58Е-ТВ.42.00.00: 58Е-ТВ.40.06.00 Кронштейн 58Е-ТВ.40.08.00 Опора 58Е-ТВ.42.01.00 Балка передняя 58Е-ТВ.42.02.00 Балка задняя 58Е-ТВ.40.05.00 Кронштейн | C30: =H30/F30 -> 0 | E30: =F30*429 -> 41184 | F30: 96 | G30: =февраль!N30:N36 -> 0 | H30: =февраль!O30:O36 -> 0 | I30: =E30/F30*J30 -> 0 | N30: =G30+SUM(I30:I36) -> 0 | O30: =H30+SUM(J30:J36) -> 0 | P30: =O30/F30 -> 0 | Q30: =F30-O30 -> 96 | R30: =1-N30/E30 -> 1 | S30: =E30-N30 -> 41184
I31: =E30/F30*J31 -> 0
I32: =E30/F30*J32 -> 0
I33: =E30/F30*J33 -> 0
I34: =E30/F30*J34 -> 0
I35: =E30/F30*J35 -> 0
I36: =E30/F30*J36 -> 0
A37: 1.3. | B37: Элементы: /Пульт оператора 58Е-ТВ.10.20.00, /Бампер 58Е-ТВ.28.110.00 /Ящики задние 58Е-ТВ.28.10.00_58Е-ТВ.28.20.00 /площадка оператора 58Е-ТВ.10.25.00 /кронштейн сидения оператора 58Е-ТВ.28.30.10 /крылья 58Е-ТВ.01.50.00 /колпаки 58Е-ТВ.10.100.00 /стойка 58Е-ТВ.28.40.00 /маслобак 58А-ТВ.12.10.00 /кронштейн транспортного положения стрелы 58Е-ТВ.50.40.74-84 (6 поз.) /кронштейны под элементы гидравлики в поворотной колонне, раме, /Лестница 58Е-ТВ.28.70.00 (боковые ступени) | C37: =H37/F37 -> 0 | E37: =F37*429 -> 71214 | F37: 166 | G37: =февраль!N37:N43 -> 0 | H37: =февраль!O37:O43 -> 0 | I37: =E37/F37*J37 -> 0 | N37: =G37+SUM(I37:I43) -> 0 | O37: =H37+SUM(J37:J43) -> 0 | P37: =O37/F37 -> 0 | Q37: =F37-O37 -> 166 | R37: =1-N37/E37 -> 1 | S37: =E37-N37 -> 71214
I38: =E37/F37*J38 -> 0
I39: =E37/F37*J39 -> 0
I40: =E37/F37*J40 -> 0
I41: =E37/F37*J41 -> 0
I42: =E37/F37*J42 -> 0
I43: =E37/F37*J43 -> 0
A44: 1.4. | B44: Поворотная колонна 58Е-ТВ.46.01.00: 58Д-ТВ.45.10.20 Кронштейн 58Е-ТВ.46.01.10 Балка 58Е-ТВ.46.10.10 Боковина правая 58Е-ТВ.46.10.10-01 Боковина левая | C44: =H44/F44 -> 0 | D44: =E44/E$177 -> 0.052227343 | E44: =F44*429 -> 29172 | F44: 68 | G44: =февраль!N44:N50 -> 0 | H44: =февраль!O44:O50 -> 0 | I44: =E44/F44*J44 -> 0 | N44: =G44+SUM(I44:I50) -> 0 | O44: =H44+SUM(J44:J50) -> 0 | P44: =O44/F44 -> 0 | Q44: =F44-O44 -> 68 | R44: =1-N44/E44 -> 1 | S44: =E44-N44 -> 29172
I45: =E44/F44*J45 -> 0
I46: =E44/F44*J46 -> 0
I47: =E44/F44*J47 -> 0
I48: =E44/F44*J48 -> 0
I49: =E44/F44*J49 -> 0
...

Sheet апрель
B1: ООО "ПК "Техинком-Центр"
A3: Наряд на оплату труда №_____ от "___" августа 2023 г.
F4: Изделие : | H4: =C6 -> ПСС-131.22Э (С42А43) 58Е-ТВ Садко НЕКСТ
B6: Продукция: | C6: =март!C6 -> ПСС-131.22Э (С42А43) 58Е-ТВ Садко НЕКСТ
B7: Подразделение: высотная техника
B8: Заводской номер: | C8: =март!C8 -> №011
B9: Количество: | F9: 1 | G9: шт.
B10: Общий фонд по машине | F10: =E177 -> 558558 | G10: руб.
B11: Трудоемкость | F11: =F177 -> 1302 | G11: н/час
B12: Стоимость н/ч (руб) | F12: =E177/F177 -> 429 | G12: руб.
A14: № | B14: Наименование операции | C14: % выполнения операции на начало месяца | D14: Справочно % от суммы наряда | E14: Утвержденные расценки и н/ч | G14: Факт выполнения нарастающим итогом на 01.04.2024г. | I14: Факт выполнения за АПРЕЛЬ 2024г. | K14: Исполнитель (ФИО) | N14: Отработано на 30.04.2024г. | P14: % выполнения операции на конец месяца | Q14: Остаток на конец месяца н/ч | R14: Отклонение на конец месяца
A15: п/п | E15: расценка за операцию (руб.) | F15: нормо-час (н/ч) | G15: (руб.) | H15: (н/ч) | I15: Стоимость (руб.) | J15: факт выполнения (н/ч) | K15: з/плата (сделка) | L15: договор ГПХ | M15: подряд | N15: сумма (руб.) | O15: н/ч. | R15: % | S15: рубли
A16: 1 | B16: Сварка-сборка узлов | C16: =H16/F16 -> 0 | D16: =E16/E$177 -> 0.59600614 | E16: =SUM(E23:E92) -> 332904 | F16: =SUM(F23:F92) -> 776 | G16: =SUM(G23:G92) -> 0 | H16: =SUM(H23:H92) -> 0 | I16: =SUM(I23:I92) -> 0 | J16: =SUM(J23:J92) -> 0 | N16: =SUM(N23:N92) -> 0 | O16: =SUM(O23:O92) -> 0 | P16: =O16/F16 -> 0 | Q16: =F16-O16 -> 776 | R16: =1-N16/E16 -> 1 | S16: =E16-N16 -> 332904
A23: 1.1. | B23: Рама опорная 58Е-ТВ.40.00.00-02: 58Е-ТВ.40.01.00 Балка/58Е-ТВ.40.01.00-01 Балка 58Е-ТВ.40.02.00 Балка задних опор 58Е-ТВ.40.03.00-01 Опора 58Б-ТВ.40.12.00 Кронштейн 58Г-ТВ.40.00.40 Кронштейн ручного насоса 58Б-ТВ.00.10.00 Кронштейн 58Б-ТВ.40.12.00 Кронштейн 58Д-ТВ.40.02.10 Кронштейн/58Д-ТВ.40.02.10-01 Кронштейн | C23: =H23/F23 -> 0 | E23: =F23*429 -> 46332 | F23: 108 | G23: =март!N23 -> 0 | H23: =март!O23 -> 0 | I23: =E23/F23*J23 -> 0 | N23: =G23+SUM(I23:I29) -> 0 | O23: =H23+SUM(J23:J29) -> 0 | P23: =O23/F23 -> 0 | Q23: =F23-O23 -> 108 | R23: =1-N23/E23 -> 1 | S23: =E23-N23 -> 46332
I24: =E23/F23*J24 -> 0
I25: =E23/F23*J25 -> 0
I26: =E23/F23*J26 -> 0
I27: =E23/F23*J27 -> 0
I28: =E23/F23*J28 -> 0
I29: =E23/F23*J29 -> 0
A30: 1.2. | B30: Аутригеры 58Е-ТВ.42.00.00: 58Е-ТВ.40.06.00 Кронштейн 58Е-ТВ.40.08.00 Опора 58Е-ТВ.42.01.00 Балка передняя 58Е-ТВ.42.02.00 Балка задняя 58Е-ТВ.40.05.00 Кронштейн | C30: =H30/F30 -> 0 | E30: =F30*429 -> 41184 | F30: 96 | G30: =март!N30 -> 0 | H30: =март!O30 -> 0 | I30: =E30/F30*J30 -> 0 | N30: =G30+SUM(I30:I36) -> 0 | O30: =H30+SUM(J30:J36) -> 0 | P30: =O30/F30 -> 0 | Q30: =F30-O30 -> 96 | R30: =1-N30/E30 -> 1 | S30: =E30-N30 -> 41184
I31: =E30/F30*J31 -> 0
I32: =E30/F30*J32 -> 0
I33: =E30/F30*J33 -> 0
I34: =E30/F30*J34 -> 0
I35: =E30/F30*J35 -> 0
I36: =E30/F30*J36 -> 0
A37: 1.3. | B37: Элементы: /Пульт оператора 58Е-ТВ.10.20.00, /Бампер 58Е-ТВ.28.110.00 /Ящики задние 58Е-ТВ.28.10.00_58Е-ТВ.28.20.00 /площадка оператора 58Е-ТВ.10.25.00 /кронштейн сидения оператора 58Е-ТВ.28.30.10 /крылья 58Е-ТВ.01.50.00 /колпаки 58Е-ТВ.10.100.00 /стойка 58Е-ТВ.28.40.00 /маслобак 58А-ТВ.12.10.00 /кронштейн транспортного положения стрелы 58Е-ТВ.50.40.74-84 (6 поз.) /кронштейны под элементы гидравлики в поворотной колонне, раме, /Лестница 58Е-ТВ.28.70.00 (боковые ступени) | C37: =H37/F37 -> 0 | E37: =F37*429 -> 71214 | F37: 166 | G37: =март!N37 -> 0 | H37: =март!O37 -> 0 | I37: =E37/F37*J37 -> 0 | N37: =G37+SUM(I37:I43) -> 0 | O37: =H37+SUM(J37:J43) -> 0 | P37: =O37/F37 -> 0 | Q37: =F37-O37 -> 166 | R37: =1-N37/E37 -> 1 | S37: =E37-N37 -> 71214
I38: =E37/F37*J38 -> 0
I39: =E37/F37*J39 -> 0
I40: =E37/F37*J40 -> 0
I41: =E37/F37*J41 -> 0
I42: =E37/F37*J42 -> 0
I43: =E37/F37*J43 -> 0
A44: 1.4. | B44: Поворотная колонна 58Е-ТВ.46.01.00: 58Д-ТВ.45.10.20 Кронштейн 58Е-ТВ.46.01.10 Балка 58Е-ТВ.46.10.10 Боковина правая 58Е-ТВ.46.10.10-01 Боковина левая | C44: =H44/F44 -> 0 | D44: =E44/E$177 -> 0.052227343 | E44: =F44*429 -> 29172 | F44: 68 | G44: =март!N44 -> 0 | H44: =март!O44 -> 0 | I44: =E44/F44*J44 -> 0 | N44: =G44+SUM(I44:I50) -> 0 | O44: =H44+SUM(J44:J50) -> 0 | P44: =O44/F44 -> 0 | Q44: =F44-O44 -> 68 | R44: =1-N44/E44 -> 1 | S44: =E44-N44 -> 29172
I45: =E44/F44*J45 -> 0
I46: =E44/F44*J46 -> 0
I47: =E44/F44*J47 -> 0
I48: =E44/F44*J48 -> 0
I49: =E44/F44*J49 -> 0
...

Sheet май
B1: ООО "ПК "Техинком-Центр"
A3: Наряд на оплату труда №_____ от "___" _______________20___г.
F4: Изделие : | H4: =C6 -> ПСС-131.22Э (С42А43) 58Е-ТВ Садко НЕКСТ
B6: Продукция: | C6: =апрель!C6 -> ПСС-131.22Э (С42А43) 58Е-ТВ Садко НЕКСТ
B7: Подразделение: высотная техника
B8: Заводской номер: | C8: =апрель!C8 -> №011
B9: Количество: | F9: 1 | G9: шт.
B10: Общий фонд по машине | F10: =E177 -> 558558 | G10: руб.
B11: Трудоемкость | F11: =F177 -> 1302 | G11: н/час
B12: Стоимость н/ч (руб) | F12: =E177/F177 -> 429 | G12: руб.
A14: № | B14: Наименование операции | C14: % выполнения операции на начало месяца | D14: Справочно % от суммы наряда | E14: Утвержденные расценки и н/ч | G14: Факт выполнения нарастающим итогом на 01.05.2024г. | I14: Факт выполнения за МАЙ 2024г. | K14: Исполнитель (ФИО) | N14: Отработано на 31.05.2024г. | P14: % выполнения операции на конец месяца | Q14: Остаток на конец месяца н/ч | R14: Отклонение на конец месяца
A15: п/п | E15: расценка за операцию (руб.) | F15: нормо-час (н/ч) | G15: (руб.) | H15: (н/ч) | I15: Стоимость (руб.) | J15: факт выполнения (н/ч) | K15: з/плата (сделка) | L15: договор ГПХ | M15: подряд | N15: сумма (руб.) | O15: н/ч. | R15: % | S15: рубли
A16: 1 | B16: Сварка-сборка узлов | C16: =H16/F16 -> 0 | D16: =E16/E$177 -> 0.59600614 | E16: =SUM(E23:E92) -> 332904 | F16: =SUM(F23:F92) -> 776 | G16: =SUM(G23:G92) -> 0 | H16: =SUM(H23:H92) -> 0 | I16: =SUM(I23:I92) -> 0 | J16: =SUM(J23:J92) -> 0 | N16: =SUM(N23:N92) -> 0 | O16: =SUM(O23:O92) -> 0 | P16: =O16/F16 -> 0 | Q16: =F16-O16 -> 776 | R16: =1-N16/E16 -> 1 | S16: =E16-N16 -> 332904
A23: 1.1. | B23: Рама опорная 58Е-ТВ.40.00.00-02: 58Е-ТВ.40.01.00 Балка/58Е-ТВ.40.01.00-01 Балка 58Е-ТВ.40.02.00 Балка задних опор 58Е-ТВ.40.03.00-01 Опора 58Б-ТВ.40.12.00 Кронштейн 58Г-ТВ.40.00.40 Кронштейн ручного насоса 58Б-ТВ.00.10.00 Кронштейн 58Б-ТВ.40.12.00 Кронштейн 58Д-ТВ.40.02.10 Кронштейн/58Д-ТВ.40.02.10-01 Кронштейн | C23: =H23/F23 -> 0 | E23: =F23*429 -> 46332 | F23: 108 | G23: =апрель!N23:N29 -> 0 | H23: =апрель!O23:O29 -> 0 | I23: =E23/F23*J23 -> 0 | N23: =G23+SUM(I23:I29) -> 0 | O23: =H23+SUM(J23:J29) -> 0 | P23: =O23/F23 -> 0 | Q23: =F23-O23 -> 108 | R23: =1-N23/E23 -> 1 | S23: =E23-N23 -> 46332
I24: =E23/F23*J24 -> 0
I25: =E23/F23*J25 -> 0
I26: =E23/F23*J26 -> 0
I27: =E23/F23*J27 -> 0
I28: =E23/F23*J28 -> 0
I29: =E23/F23*J29 -> 0
A30: 1.2. | B30: Аутригеры 58Е-ТВ.42.00.00: 58Е-ТВ.40.06.00 Кронштейн 58Е-ТВ.40.08.00 Опора 58Е-ТВ.42.01.00 Балка передняя 58Е-ТВ.42.02.00 Балка задняя 58Е-ТВ.40.05.00 Кронштейн | C30: =H30/F30 -> 0 | E30: =F30*429 -> 41184 | F30: 96 | G30: =апрель!N30:N36 -> 0 | H30: =апрель!O30:O36 -> 0 | I30: =E30/F30*J30 -> 0 | N30: =G30+SUM(I30:I36) -> 0 | O30: =H30+SUM(J30:J36) -> 0 | P30: =O30/F30 -> 0 | Q30: =F30-O30 -> 96 | R30: =1-N30/E30 -> 1 | S30: =E30-N30 -> 41184
I31: =E30/F30*J31 -> 0
I32: =E30/F30*J32 -> 0
I33: =E30/F30*J33 -> 0
I34: =E30/F30*J34 -> 0
I35: =E30/F30*J35 -> 0
I36: =E30/F30*J36 -> 0
A37: 1.3. | B37: Элементы: /Пульт оператора 58Е-ТВ.10.20.00, /Бампер 58Е-ТВ.28.110.00 /Ящики задние 58Е-ТВ.28.10.00_58Е-ТВ.28.20.00 /площадка оператора 58Е-ТВ.10.25.00 /кронштейн сидения оператора 58Е-ТВ.28.30.10 /крылья 58Е-ТВ.01.50.00 /колпаки 58Е-ТВ.10.100.00 /стойка 58Е-ТВ.28.40.00 /маслобак 58А-ТВ.12.10.00 /кронштейн транспортного положения стрелы 58Е-ТВ.50.40.74-84 (6 поз.) /кронштейны под элементы гидравлики в поворотной колонне, раме, /Лестница 58Е-ТВ.28.70.00 (боковые ступени) | C37: =H37/F37 -> 0 | E37: =F37*429 -> 71214 | F37: 166 | G37: =апрель!N37:N43 -> 0 | H37: =апрель!O37:O43 -> 0 | I37: =E37/F37*J37 -> 0 | N37: =G37+SUM(I37:I43) -> 0 | O37: =H37+SUM(J37:J43) -> 0 | P37: =O37/F37 -> 0 | Q37: =F37-O37 -> 166 | R37: =1-N37/E37 -> 1 | S37: =E37-N37 -> 71214
I38: =E37/F37*J38 -> 0
I39: =E37/F37*J39 -> 0
I40: =E37/F37*J40 -> 0
I41: =E37/F37*J41 -> 0
I42: =E37/F37*J42 -> 0
I43: =E37/F37*J43 -> 0
A44: 1.4. | B44: Поворотная колонна 58Е-ТВ.46.01.00: 58Д-ТВ.45.10.20 Кронштейн 58Е-ТВ.46.01.10 Балка 58Е-ТВ.46.10.10 Боковина правая 58Е-ТВ.46.10.10-01 Боковина левая | C44: =H44/F44 -> 0 | D44: =E44/E$177 -> 0.052227343 | E44: =F44*429 -> 29172 | F44: 68 | G44: =апрель!N44:N50 -> 0 | H44: =апрель!O44:O50 -> 0 | I44: =E44/F44*J44 -> 0 | N44: =G44+SUM(I44:I50) -> 0 | O44: =H44+SUM(J44:J50) -> 0 | P44: =O44/F44 -> 0 | Q44: =F44-O44 -> 68 | R44: =1-N44/E44 -> 1 | S44: =E44-N44 -> 29172
I45: =E44/F44*J45 -> 0
I46: =E44/F44*J46 -> 0
I47: =E44/F44*J47 -> 0
I48: =E44/F44*J48 -> 0
I49: =E44/F44*J49 -> 0
...

Sheet июнь
B1: ООО "ПК "Техинком-Центр"
A3: Наряд на оплату труда №_____ от "___" _______________20___г.
F4: Изделие : | H4: =C6 -> ПСС-131.22Э (С42А43) 58Е-ТВ Садко НЕКСТ
B6: Продукция: | C6: =май!C6 -> ПСС-131.22Э (С42А43) 58Е-ТВ Садко НЕКСТ
B7: Подразделение: высотная техника
B8: Заводской номер: | C8: =май!C8 -> №011
B9: Количество: | F9: 1 | G9: шт.
B10: Общий фонд по машине | F10: =E177 -> 558558 | G10: руб.
B11: Трудоемкость | F11: =F177 -> 1302 | G11: н/час
B12: Стоимость н/ч (руб) | F12: =E177/F177 -> 429 | G12: руб.
A14: № | B14: Наименование операции | C14: % выполнения операции на начало месяца | D14: Справочно % от суммы наряда | E14: Утвержденные расценки и н/ч | G14: Факт выполнения нарастающим итогом на 01.06.2024г. | I14: Факт выполнения за ИЮНЬ 2024г. | K14: Исполнитель (ФИО) | N14: Отработано на 30.06.2024г. | P14: % выполнения операции на конец месяца | Q14: Остаток на конец месяца н/ч | R14: Отклонение на конец месяца
A15: п/п | E15: расценка за операцию (руб.) | F15: нормо-час (н/ч) | G15: (руб.) | H15: (н/ч) | I15: Стоимость (руб.) | J15: факт выполнения (н/ч) | K15: з/плата (сделка) | L15: договор ГПХ | M15: подряд | N15: сумма (руб.) | O15: н/ч. | R15: % | S15: рубли
A16: 1 | B16: Сварка-сборка узлов | C16: =H16/F16 -> 0 | D16: =E16/E$177 -> 0.59600614 | E16: =SUM(E23:E92) -> 332904 | F16: =SUM(F23:F92) -> 776 | G16: =SUM(G23:G92) -> 0 | H16: =SUM(H23:H92) -> 0 | I16: =SUM(I23:I92) -> 0 | J16: =SUM(J23:J92) -> 0 | N16: =SUM(N23:N92) -> 0 | O16: =SUM(O23:O92) -> 0 | P16: =O16/F16 -> 0 | Q16: =F16-O16 -> 776 | R16: =1-N16/E16 -> 1 | S16: =E16-N16 -> 332904
A23: 1.1. | B23: Рама опорная 58Е-ТВ.40.00.00-02: 58Е-ТВ.40.01.00 Балка/58Е-ТВ.40.01.00-01 Балка 58Е-ТВ.40.02.00 Балка задних опор 58Е-ТВ.40.03.00-01 Опора 58Б-ТВ.40.12.00 Кронштейн 58Г-ТВ.40.00.40 Кронштейн ручного насоса 58Б-ТВ.00.10.00 Кронштейн 58Б-ТВ.40.12.00 Кронштейн 58Д-ТВ.40.02.10 Кронштейн/58Д-ТВ.40.02.10-01 Кронштейн | C23: =H23/F23 -> 0 | E23: =F23*429 -> 46332 | F23: 108 | G23: =май!N23:N29 -> 0 | H23: =май!O23:O29 -> 0 | I23: =E23/F23*J23 -> 0 | N23: =G23+SUM(I23:I29) -> 0 | O23: =H23+SUM(J23:J29) -> 0 | P23: =O23/F23 -> 0 | Q23: =F23-O23 -> 108 | R23: =1-N23/E23 -> 1 | S23: =E23-N23 -> 46332
I24: =E23/F23*J24 -> 0
I25: =E23/F23*J25 -> 0
I26: =E23/F23*J26 -> 0
I27: =E23/F23*J27 -> 0
I28: =E23/F23*J28 -> 0
I29: =E23/F23*J29 -> 0
A30: 1.2. | B30: Аутригеры 58Е-ТВ.42.00.00: 58Е-ТВ.40.06.00 Кронштейн 58Е-ТВ.40.08.00 Опора 58Е-ТВ.42.01.00 Балка передняя 58Е-ТВ.42.02.00 Балка задняя 58Е-ТВ.40.05.00 Кронштейн | C30: =H30/F30 -> 0 | E30: =F30*429 -> 41184 | F30: 96 | G30: =май!N30:N36 -> 0 | H30: =май!O30:O36 -> 0 | I30: =E30/F30*J30 -> 0 | N30: =G30+SUM(I30:I36) -> 0 | O30: =H30+SUM(J30:J36) -> 0 | P30: =O30/F30 -> 0 | Q30: =F30-O30 -> 96 | R30: =1-N30/E30 -> 1 | S30: =E30-N30 -> 41184
I31: =E30/F30*J31 -> 0
I32: =E30/F30*J32 -> 0
I33: =E30/F30*J33 -> 0
I34: =E30/F30*J34 -> 0
I35: =E30/F30*J35 -> 0
I36: =E30/F30*J36 -> 0
A37: 1.3. | B37: Элементы: /Пульт оператора 58Е-ТВ.10.20.00, /Бампер 58Е-ТВ.28.110.00 /Ящики задние 58Е-ТВ.28.10.00_58Е-ТВ.28.20.00 /площадка оператора 58Е-ТВ.10.25.00 /кронштейн сидения оператора 58Е-ТВ.28.30.10 /крылья 58Е-ТВ.01.50.00 /колпаки 58Е-ТВ.10.100.00 /стойка 58Е-ТВ.28.40.00 /маслобак 58А-ТВ.12.10.00 /кронштейн транспортного положения стрелы 58Е-ТВ.50.40.74-84 (6 поз.) /кронштейны под элементы гидравлики в поворотной колонне, раме, /Лестница 58Е-ТВ.28.70.00 (боковые ступени) | C37: =H37/F37 -> 0 | E37: =F37*429 -> 71214 | F37: 166 | G37: =май!N37:N43 -> 0 | H37: =май!O37:O43 -> 0 | I37: =E37/F37*J37 -> 0 | N37: =G37+SUM(I37:I43) -> 0 | O37: =H37+SUM(J37:J43) -> 0 | P37: =O37/F37 -> 0 | Q37: =F37-O37 -> 166 | R37: =1-N37/E37 -> 1 | S37: =E37-N37 -> 71214
I38: =E37/F37*J38 -> 0
I39: =E37/F37*J39 -> 0
I40: =E37/F37*J40 -> 0
I41: =E37/F37*J41 -> 0
I42: =E37/F37*J42 -> 0
I43: =E37/F37*J43 -> 0
A44: 1.4. | B44: Поворотная колонна 58Е-ТВ.46.01.00: 58Д-ТВ.45.10.20 Кронштейн 58Е-ТВ.46.01.10 Балка 58Е-ТВ.46.10.10 Боковина правая 58Е-ТВ.46.10.10-01 Боковина левая | C44: =H44/F44 -> 0 | D44: =E44/E$177 -> 0.052227343 | E44: =F44*429 -> 29172 | F44: 68 | G44: =май!N44:N50 -> 0 | H44: =май!O44:O50 -> 0 | I44: =E44/F44*J44 -> 0 | N44: =G44+SUM(I44:I50) -> 0 | O44: =H44+SUM(J44:J50) -> 0 | P44: =O44/F44 -> 0 | Q44: =F44-O44 -> 68 | R44: =1-N44/E44 -> 1 | S44: =E44-N44 -> 29172
I45: =E44/F44*J45 -> 0
I46: =E44/F44*J46 -> 0
I47: =E44/F44*J47 -> 0
I48: =E44/F44*J48 -> 0
I49: =E44/F44*J49 -> 0
...

Sheet июль
B1: ООО "ПК "Техинком-Центр"
A3: Наряд на оплату труда №_____ от "___" _______________20___г.
F4: Изделие : | H4: =C6 -> ПСС-131.22Э (С42А43) 58Е-ТВ Садко НЕКСТ
B6: Продукция: | C6: =июнь!C6 -> ПСС-131.22Э (С42А43) 58Е-ТВ Садко НЕКСТ
B7: Подразделение: высотная техника
B8: Заводской номер: | C8: =июнь!C8 -> №011
B9: Количество: | F9: 1 | G9: шт.
B10: Общий фонд по машине | F10: =E177 -> 558558 | G10: руб.
B11: Трудоемкость | F11: =F177 -> 1302 | G11: н/час
B12: Стоимость н/ч (руб) | F12: =E177/F177 -> 429 | G12: руб.
A14: № | B14: Наименование операции | C14: % выполнения операции на начало месяца | D14: Справочно % от суммы наряда | E14: Утвержденные расценки и н/ч | G14: Факт выполнения нарастающим итогом на 01.07.2024 | I14: Факт выполнения за ИЮЛЬ 2024 | K14: Исполнитель (ФИО) | N14: Отработано на 31.07.2024 | P14: % выполнения операции на конец месяца | Q14: Остаток на конец месяца н/ч | R14: Отклонение на конец месяца
A15: п/п | E15: расценка за операцию (руб.) | F15: нормо-час (н/ч) | G15: (руб.) | H15: (н/ч) | I15: Стоимость (руб.) | J15: факт выполнения (н/ч) | K15: з/плата (сделка) | L15: договор ГПХ | M15: подряд | N15: сумма (руб.) | O15: н/ч. | R15: % | S15: рубли
A16: 1 | B16: Сварка-сборка узлов | C16: =H16/F16 -> 0 | D16: =E16/E$177 -> 0.59600614 | E16: =SUM(E23:E92) -> 332904 | F16: =SUM(F23:F92) -> 776 | G16: =SUM(G23:G92) -> 0 | H16: =SUM(H23:H92) -> 0 | I16: =SUM(I23:I92) -> 0 | J16: =SUM(J23:J92) -> 0 | N16: =SUM(N23:N92) -> 0 | O16: =SUM(O23:O92) -> 0 | P16: =O16/F16 -> 0 | Q16: =F16-O16 -> 776 | R16: =1-N16/E16 -> 1 | S16: =E16-N16 -> 332904
A23: 1.1. | B23: Рама опорная 58Е-ТВ.40.00.00-02: 58Е-ТВ.40.01.00 Балка/58Е-ТВ.40.01.00-01 Балка 58Е-ТВ.40.02.00 Балка задних опор 58Е-ТВ.40.03.00-01 Опора 58Б-ТВ.40.12.00 Кронштейн 58Г-ТВ.40.00.40 Кронштейн ручного насоса 58Б-ТВ.00.10.00 Кронштейн 58Б-ТВ.40.12.00 Кронштейн 58Д-ТВ.40.02.10 Кронштейн/58Д-ТВ.40.02.10-01 Кронштейн | C23: =H23/F23 -> 0 | E23: =F23*429 -> 46332 | F23: 108 | G23: =июнь!N23:N29 -> 0 | H23: =июнь!O23:O29 -> 0 | I23: =E23/F23*J23 -> 0 | N23: =G23+SUM(I23:I29) -> 0 | O23: =H23+SUM(J23:J29) -> 0 | P23: =O23/F23 -> 0 | Q23: =F23-O23 -> 108 | R23: =1-N23/E23 -> 1 | S23: =E23-N23 -> 46332
I24: =E23/F23*J24 -> 0
I25: =E23/F23*J25 -> 0
I26: =E23/F23*J26 -> 0
I27: =E23/F23*J27 -> 0
I28: =E23/F23*J28 -> 0
I29: =E23/F23*J29 -> 0
A30: 1.2. | B30: Аутригеры 58Е-ТВ.42.00.00: 58Е-ТВ.40.06.00 Кронштейн 58Е-ТВ.40.08.00 Опора 58Е-ТВ.42.01.00 Балка передняя 58Е-ТВ.42.02.00 Балка задняя 58Е-ТВ.40.05.00 Кронштейн | C30: =H30/F30 -> 0 | E30: =F30*429 -> 41184 | F30: 96 | G30: =июнь!N30:N36 -> 0 | H30: =июнь!O30:O36 -> 0 | I30: =E30/F30*J30 -> 0 | N30: =G30+SUM(I30:I36) -> 0 | O30: =H30+SUM(J30:J36) -> 0 | P30: =O30/F30 -> 0 | Q30: =F30-O30 -> 96 | R30: =1-N30/E30 -> 1 | S30: =E30-N30 -> 41184
I31: =E30/F30*J31 -> 0
I32: =E30/F30*J32 -> 0
I33: =E30/F30*J33 -> 0
I34: =E30/F30*J34 -> 0
I35: =E30/F30*J35 -> 0
I36: =E30/F30*J36 -> 0
A37: 1.3. | B37: Элементы: /Пульт оператора 58Е-ТВ.10.20.00, /Бампер 58Е-ТВ.28.110.00 /Ящики задние 58Е-ТВ.28.10.00_58Е-ТВ.28.20.00 /площадка оператора 58Е-ТВ.10.25.00 /кронштейн сидения оператора 58Е-ТВ.28.30.10 /крылья 58Е-ТВ.01.50.00 /колпаки 58Е-ТВ.10.100.00 /стойка 58Е-ТВ.28.40.00 /маслобак 58А-ТВ.12.10.00 /кронштейн транспортного положения стрелы 58Е-ТВ.50.40.74-84 (6 поз.) /кронштейны под элементы гидравлики в поворотной колонне, раме, /Лестница 58Е-ТВ.28.70.00 (боковые ступени) | C37: =H37/F37 -> 0 | E37: =F37*429 -> 71214 | F37: 166 | G37: =июнь!N37:N43 -> 0 | H37: =июнь!O37:O43 -> 0 | I37: =E37/F37*J37 -> 0 | N37: =G37+SUM(I37:I43) -> 0 | O37: =H37+SUM(J37:J43) -> 0 | P37: =O37/F37 -> 0 | Q37: =F37-O37 -> 166 | R37: =1-N37/E37 -> 1 | S37: =E37-N37 -> 71214
I38: =E37/F37*J38 -> 0
I39: =E37/F37*J39 -> 0
I40: =E37/F37*J40 -> 0
I41: =E37/F37*J41 -> 0
I42: =E37/F37*J42 -> 0
I43: =E37/F37*J43 -> 0
A44: 1.4. | B44: Поворотная колонна 58Е-ТВ.46.01.00: 58Д-ТВ.45.10.20 Кронштейн 58Е-ТВ.46.01.10 Балка 58Е-ТВ.46.10.10 Боковина правая 58Е-ТВ.46.10.10-01 Боковина левая | C44: =H44/F44 -> 0 | D44: =E44/E$177 -> 0.052227343 | E44: =F44*429 -> 29172 | F44: 68 | G44: =июнь!N44:N50 -> 0 | H44: =июнь!O44:O50 -> 0 | I44: =E44/F44*J44 -> 0 | N44: =G44+SUM(I44:I50) -> 0 | O44: =H44+SUM(J44:J50) -> 0 | P44: =O44/F44 -> 0 | Q44: =F44-O44 -> 68 | R44: =1-N44/E44 -> 1 | S44: =E44-N44 -> 29172
I45: =E44/F44*J45 -> 0
I46: =E44/F44*J46 -> 0
I47: =E44/F44*J47 -> 0
I48: =E44/F44*J48 -> 0
I49: =E44/F44*J49 -> 0
...

Sheet август
B1: ООО "ПК "Техинком-Центр"
A3: Наряд на оплату труда №_____ от "___" _______________20___г.
F4: Изделие : | H4: =C6 -> ПСС-131.22Э (С42А43) 58Е-ТВ Садко НЕКСТ
B6: Продукция: | C6: =июль!C6 -> ПСС-131.22Э (С42А43) 58Е-ТВ Садко НЕКСТ
B7: Подразделение: высотная техника
B8: Заводской номер: | C8: =июль!C8 -> №011
B9: Количество: | F9: 1 | G9: шт.
B10: Общий фонд по машине | F10: =E177 -> 558558 | G10: руб.
B11: Трудоемкость | F11: =F177 -> 1302 | G11: н/час
B12: Стоимость н/ч (руб) | F12: =E177/F177 -> 429 | G12: руб.
A14: № | B14: Наименование операции | C14: % выполнения операции на начало месяца | D14: Справочно % от суммы наряда | E14: Утвержденные расценки и н/ч | G14: Факт выполнения нарастающим итогом на 01.08.2024 | I14: Факт выполнения за АВГУСТ 2024 | K14: Исполнитель (ФИО) | N14: Отработано на 31.08.2024 | P14: % выполнения операции на конец месяца | Q14: Остаток на конец месяца н/ч | R14: Отклонение на конец месяца
A15: п/п | E15: расценка за операцию (руб.) | F15: нормо-час (н/ч) | G15: (руб.) | H15: (н/ч) | I15: Стоимость (руб.) | J15: факт выполнения (н/ч) | K15: з/плата (сделка) | L15: договор ГПХ | M15: подряд | N15: сумма (руб.) | O15: н/ч. | R15: % | S15: рубли
A16: 1 | B16: Сварка-сборка узлов | C16: =H16/F16 -> 0 | D16: =E16/E$177 -> 0.59600614 | E16: =SUM(E23:E92) -> 332904 | F16: =SUM(F23:F92) -> 776 | G16: =SUM(G23:G92) -> 0 | H16: =SUM(H23:H92) -> 0 | I16: =SUM(I23:I92) -> 0 | J16: =SUM(J23:J92) -> 0 | N16: =SUM(N23:N92) -> 0 | O16: =SUM(O23:O92) -> 0 | P16: =O16/F16 -> 0 | Q16: =F16-O16 -> 776 | R16: =1-N16/E16 -> 1 | S16: =E16-N16 -> 332904
A23: 1.1. | B23: Рама опорная 58Е-ТВ.40.00.00-02: 58Е-ТВ.40.01.00 Балка/58Е-ТВ.40.01.00-01 Балка 58Е-ТВ.40.02.00 Балка задних опор 58Е-ТВ.40.03.00-01 Опора 58Б-ТВ.40.12.00 Кронштейн 58Г-ТВ.40.00.40 Кронштейн ручного насоса 58Б-ТВ.00.10.00 Кронштейн 58Б-ТВ.40.12.00 Кронштейн 58Д-ТВ.40.02.10 Кронштейн/58Д-ТВ.40.02.10-01 Кронштейн | C23: =H23/F23 -> 0 | E23: =F23*429 -> 46332 | F23: 108 | G23: =июль!N23:N29 -> 0 | H23: =июль!O23:O29 -> 0 | I23: =E23/F23*J23 -> 0 | N23: =G23+SUM(I23:I29) -> 0 | O23: =H23+SUM(J23:J29) -> 0 | P23: =O23/F23 -> 0 | Q23: =F23-O23 -> 108 | R23: =1-N23/E23 -> 1 | S23: =E23-N23 -> 46332
I24: =E23/F23*J24 -> 0
I25: =E23/F23*J25 -> 0
I26: =E23/F23*J26 -> 0
I27: =E23/F23*J27 -> 0
I28: =E23/F23*J28 -> 0
I29: =E23/F23*J29 -> 0
A30: 1.2. | B30: Аутригеры 58Е-ТВ.42.00.00: 58Е-ТВ.40.06.00 Кронштейн 58Е-ТВ.40.08.00 Опора 58Е-ТВ.42.01.00 Балка передняя 58Е-ТВ.42.02.00 Балка задняя 58Е-ТВ.40.05.00 Кронштейн | C30: =H30/F30 -> 0 | E30: =F30*429 -> 41184 | F30: 96 | G30: =июль!N30:N36 -> 0 | H30: =июль!O30:O36 -> 0 | I30: =E30/F30*J30 -> 0 | N30: =G30+SUM(I30:I36) -> 0 | O30: =H30+SUM(J30:J36) -> 0 | P30: =O30/F30 -> 0 | Q30: =F30-O30 -> 96 | R30: =1-N30/E30 -> 1 | S30: =E30-N30 -> 41184
I31: =E30/F30*J31 -> 0
I32: =E30/F30*J32 -> 0
I33: =E30/F30*J33 -> 0
I34: =E30/F30*J34 -> 0
I35: =E30/F30*J35 -> 0
I36: =E30/F30*J36 -> 0
A37: 1.3. | B37: Элементы: /Пульт оператора 58Е-ТВ.10.20.00, /Бампер 58Е-ТВ.28.110.00 /Ящики задние 58Е-ТВ.28.10.00_58Е-ТВ.28.20.00 /площадка оператора 58Е-ТВ.10.25.00 /кронштейн сидения оператора 58Е-ТВ.28.30.10 /крылья 58Е-ТВ.01.50.00 /колпаки 58Е-ТВ.10.100.00 /стойка 58Е-ТВ.28.40.00 /маслобак 58А-ТВ.12.10.00 /кронштейн транспортного положения стрелы 58Е-ТВ.50.40.74-84 (6 поз.) /кронштейны под элементы гидравлики в поворотной колонне, раме, /Лестница 58Е-ТВ.28.70.00 (боковые ступени) | C37: =H37/F37 -> 0 | E37: =F37*429 -> 71214 | F37: 166 | G37: =июль!N37:N43 -> 0 | H37: =июль!O37:O43 -> 0 | I37: =E37/F37*J37 -> 0 | N37: =G37+SUM(I37:I43) -> 0 | O37: =H37+SUM(J37:J43) -> 0 | P37: =O37/F37 -> 0 | Q37: =F37-O37 -> 166 | R37: =1-N37/E37 -> 1 | S37: =E37-N37 -> 71214
I38: =E37/F37*J38 -> 0
I39: =E37/F37*J39 -> 0
I40: =E37/F37*J40 -> 0
I41: =E37/F37*J41 -> 0
I42: =E37/F37*J42 -> 0
I43: =E37/F37*J43 -> 0
A44: 1.4. | B44: Поворотная колонна 58Е-ТВ.46.01.00: 58Д-ТВ.45.10.20 Кронштейн 58Е-ТВ.46.01.10 Балка 58Е-ТВ.46.10.10 Боковина правая 58Е-ТВ.46.10.10-01 Боковина левая | C44: =H44/F44 -> 0 | D44: =E44/E$177 -> 0.052227343 | E44: =F44*429 -> 29172 | F44: 68 | G44: =июль!N44:N50 -> 0 | H44: =июль!O44:O50 -> 0 | I44: =E44/F44*J44 -> 0 | N44: =G44+SUM(I44:I50) -> 0 | O44: =H44+SUM(J44:J50) -> 0 | P44: =O44/F44 -> 0 | Q44: =F44-O44 -> 68 | R44: =1-N44/E44 -> 1 | S44: =E44-N44 -> 29172
I45: =E44/F44*J45 -> 0
I46: =E44/F44*J46 -> 0
I47: =E44/F44*J47 -> 0
I48: =E44/F44*J48 -> 0
I49: =E44/F44*J49 -> 0
...

Sheet сентябрь
B1: ООО "ПК "Техинком-Центр"
A3: Наряд на оплату труда №_____ от "___" _______________20___г.
F4: Изделие : | H4: =C6 -> ПСС-131.22Э (С42А43) 58Е-ТВ Садко НЕКСТ
B6: Продукция: | C6: =июль!C6 -> ПСС-131.22Э (С42А43) 58Е-ТВ Садко НЕКСТ
B7: Подразделение: высотная техника
B8: Заводской номер: | C8: =июль!C8 -> №011
B9: Количество: | C9: =июль!C9 -> 0 | F9: 1 | G9: шт.
B10: Общий фонд по машине | F10: =E177 -> 558558 | G10: руб.
B11: Трудоемкость | F11: =F177 -> 1302 | G11: н/час
B12: Стоимость н/ч (руб) | F12: =E177/F177 -> 429 | G12: руб.
A14: № | B14: Наименование операции | C14: % выполнения операции на начало месяца | D14: Справочно % от суммы наряда | E14: Утвержденные расценки и н/ч | G14: Факт выполнения нарастающим итогом на 01.09.2024 | I14: Факт выполнения за СЕНТЯБРЬ 2024 | K14: Исполнитель (ФИО) | N14: Отработано на 30.09.2024 | P14: % выполнения операции на конец месяца | Q14: Остаток на конец месяца н/ч | R14: Отклонение на конец месяца
A15: п/п | E15: расценка за операцию (руб.) | F15: нормо-час (н/ч) | G15: (руб.) | H15: (н/ч) | I15: Стоимость (руб.) | J15: факт выполнения (н/ч) | K15: з/плата (сделка) | L15: договор ГПХ | M15: подряд | N15: сумма (руб.) | O15: н/ч. | R15: % | S15: рубли
A16: 1 | B16: Сварка-сборка узлов | C16: =H16/F16 -> 0 | D16: =E16/E$177 -> 0.59600614 | E16: =SUM(E23:E92) -> 332904 | F16: =SUM(F23:F92) -> 776 | G16: =SUM(G23:G92) -> 0 | H16: =SUM(H23:H92) -> 0 | I16: =SUM(I23:I92) -> 0 | J16: =SUM(J23:J92) -> 0 | N16: =SUM(N23:N92) -> 0 | O16: =SUM(O23:O92) -> 0 | P16: =O16/F16 -> 0 | Q16: =F16-O16 -> 776 | R16: =1-N16/E16 -> 1 | S16: =E16-N16 -> 332904
A23: 1.1. | B23: Рама опорная 58Е-ТВ.40.00.00-02: 58Е-ТВ.40.01.00 Балка/58Е-ТВ.40.01.00-01 Балка 58Е-ТВ.40.02.00 Балка задних опор 58Е-ТВ.40.03.00-01 Опора 58Б-ТВ.40.12.00 Кронштейн 58Г-ТВ.40.00.40 Кронштейн ручного насоса 58Б-ТВ.00.10.00 Кронштейн 58Б-ТВ.40.12.00 Кронштейн 58Д-ТВ.40.02.10 Кронштейн/58Д-ТВ.40.02.10-01 Кронштейн | C23: =H23/F23 -> 0 | E23: =F23*429 -> 46332 | F23: 108 | G23: =август!N23 -> 0 | H23: =август!O23 -> 0 | I23: =E23/F23*J23 -> 0 | N23: =G23+SUM(I23:I29) -> 0 | O23: =H23+SUM(J23:J29) -> 0 | P23: =O23/F23 -> 0 | Q23: =F23-O23 -> 108 | R23: =1-N23/E23 -> 1 | S23: =E23-N23 -> 46332
I24: =E23/F23*J24 -> 0
I25: =E23/F23*J25 -> 0
I26: =E23/F23*J26 -> 0
I27: =E23/F23*J27 -> 0
I28: =E23/F23*J28 -> 0
I29: =E23/F23*J29 -> 0
A30: 1.2. | B30: Аутригеры 58Е-ТВ.42.00.00: 58Е-ТВ.40.06.00 Кронштейн 58Е-ТВ.40.08.00 Опора 58Е-ТВ.42.01.00 Балка передняя 58Е-ТВ.42.02.00 Балка задняя 58Е-ТВ.40.05.00 Кронштейн | C30: =H30/F30 -> 0 | E30: =F30*429 -> 41184 | F30: 96 | G30: =август!N30 -> 0 | H30: =август!O30 -> 0 | I30: =E30/F30*J30 -> 0 | N30: =G30+SUM(I30:I36) -> 0 | O30: =H30+SUM(J30:J36) -> 0 | P30: =O30/F30 -> 0 | Q30: =F30-O30 -> 96 | R30: =1-N30/E30 -> 1 | S30: =E30-N30 -> 41184
I31: =E30/F30*J31 -> 0
I32: =E30/F30*J32 -> 0
I33: =E30/F30*J33 -> 0
I34: =E30/F30*J34 -> 0
I35: =E30/F30*J35 -> 0
I36: =E30/F30*J36 -> 0
A37: 1.3. | B37: Элементы: /Пульт оператора 58Е-ТВ.10.20.00, /Бампер 58Е-ТВ.28.110.00 /Ящики задние 58Е-ТВ.28.10.00_58Е-ТВ.28.20.00 /площадка оператора 58Е-ТВ.10.25.00 /кронштейн сидения оператора 58Е-ТВ.28.30.10 /крылья 58Е-ТВ.01.50.00 /колпаки 58Е-ТВ.10.100.00 /стойка 58Е-ТВ.28.40.00 /маслобак 58А-ТВ.12.10.00 /кронштейн транспортного положения стрелы 58Е-ТВ.50.40.74-84 (6 поз.) /кронштейны под элементы гидравлики в поворотной колонне, раме, /Лестница 58Е-ТВ.28.70.00 (боковые ступени) | C37: =H37/F37 -> 0 | E37: =F37*429 -> 71214 | F37: 166 | G37: =август!N37 -> 0 | H37: =август!O37 -> 0 | I37: =E37/F37*J37 -> 0 | N37: =G37+SUM(I37:I43) -> 0 | O37: =H37+SUM(J37:J43) -> 0 | P37: =O37/F37 -> 0 | Q37: =F37-O37 -> 166 | R37: =1-N37/E37 -> 1 | S37: =E37-N37 -> 71214
I38: =E37/F37*J38 -> 0
I39: =E37/F37*J39 -> 0
I40: =E37/F37*J40 -> 0
I41: =E37/F37*J41 -> 0
I42: =E37/F37*J42 -> 0
I43: =E37/F37*J43 -> 0
A44: 1.4. | B44: Поворотная колонна 58Е-ТВ.46.01.00: 58Д-ТВ.45.10.20 Кронштейн 58Е-ТВ.46.01.10 Балка 58Е-ТВ.46.10.10 Боковина правая 58Е-ТВ.46.10.10-01 Боковина левая | C44: =H44/F44 -> 0 | D44: =E44/E$177 -> 0.052227343 | E44: =F44*429 -> 29172 | F44: 68 | G44: =август!N44 -> 0 | H44: =август!O44 -> 0 | I44: =E44/F44*J44 -> 0 | N44: =G44+SUM(I44:I50) -> 0 | O44: =H44+SUM(J44:J50) -> 0 | P44: =O44/F44 -> 0 | Q44: =F44-O44 -> 68 | R44: =1-N44/E44 -> 1 | S44: =E44-N44 -> 29172
I45: =E44/F44*J45 -> 0
I46: =E44/F44*J46 -> 0
I47: =E44/F44*J47 -> 0
I48: =E44/F44*J48 -> 0
I49: =E44/F44*J49 -> 0
...

Sheet октябрь
B1: ООО "ПК "Техинком-Центр"
A3: Наряд на оплату труда №_____ от "___" _______________20___г.
F4: Изделие : | H4: =C6 -> ПСС-131.22Э (С42А43) 58Е-ТВ Садко НЕКСТ
B6: Продукция: | C6: =июль!C6 -> ПСС-131.22Э (С42А43) 58Е-ТВ Садко НЕКСТ
B7: Подразделение: высотная техника
B8: Заводской номер: | C8: =июль!C8 -> №011
B9: Количество: | F9: 1 | G9: шт.
B10: Общий фонд по машине | F10: =E177 -> 558558 | G10: руб.
B11: Трудоемкость | F11: =F177 -> 1302 | G11: н/час
B12: Стоимость н/ч (руб) | F12: =E177/F177 -> 429 | G12: руб.
A14: № | B14: Наименование операции | C14: % выполнения операции на начало месяца | D14: Справочно % от суммы наряда | E14: Утвержденные расценки и н/ч | G14: Факт выполнения нарастающим итогом на 01.10.2024 | I14: Факт выполнения за ОКТЯБРЯ 2024 | K14: Исполнитель (ФИО) | N14: Отработано на 31.10.2024 | P14: % выполнения операции на конец месяца | Q14: Остаток на конец месяца н/ч | R14: Отклонение на конец месяца
A15: п/п | E15: расценка за операцию (руб.) | F15: нормо-час (н/ч) | G15: (руб.) | H15: (н/ч) | I15: Стоимость (руб.) | J15: факт выполнения (н/ч) | K15: з/плата (сделка) | L15: договор ГПХ | M15: подряд | N15: сумма (руб.) | O15: н/ч. | R15: % | S15: рубли
A16: 1 | B16: Сварка-сборка узлов | C16: =H16/F16 -> 0 | D16: =E16/E$177 -> 0.59600614 | E16: =SUM(E23:E92) -> 332904 | F16: =SUM(F23:F92) -> 776 | G16: =SUM(G23:G92) -> 0 | H16: =SUM(H23:H92) -> 0 | I16: =SUM(I23:I92) -> 0 | J16: =SUM(J23:J92) -> 0 | N16: =SUM(N23:N92) -> 0 | O16: =SUM(O23:O92) -> 0 | P16: =O16/F16 -> 0 | Q16: =F16-O16 -> 776 | R16: =1-N16/E16 -> 1 | S16: =E16-N16 -> 332904
A23: 1.1. | B23: Рама опорная 58Е-ТВ.40.00.00-02: 58Е-ТВ.40.01.00 Балка/58Е-ТВ.40.01.00-01 Балка 58Е-ТВ.40.02.00 Балка задних опор 58Е-ТВ.40.03.00-01 Опора 58Б-ТВ.40.12.00 Кронштейн 58Г-ТВ.40.00.40 Кронштейн ручного насоса 58Б-ТВ.00.10.00 Кронштейн 58Б-ТВ.40.12.00 Кронштейн 58Д-ТВ.40.02.10 Кронштейн/58Д-ТВ.40.02.10-01 Кронштейн | C23: =H23/F23 -> 0 | E23: =F23*429 -> 46332 | F23: 108 | G23: =сентябрь!N23 -> 0 | H23: =сентябрь!O23 -> 0 | I23: =E23/F23*J23 -> 0 | N23: =G23+SUM(I23:I29) -> 0 | O23: =H23+SUM(J23:J29) -> 0 | P23: =O23/F23 -> 0 | Q23: =F23-O23 -> 108 | R23: =1-N23/E23 -> 1 | S23: =E23-N23 -> 46332
I24: =E23/F23*J24 -> 0
I25: =E23/F23*J25 -> 0
I26: =E23/F23*J26 -> 0
I27: =E23/F23*J27 -> 0
I28: =E23/F23*J28 -> 0
I29: =E23/F23*J29 -> 0
A30: 1.2. | B30: Аутригеры 58Е-ТВ.42.00.00: 58Е-ТВ.40.06.00 Кронштейн 58Е-ТВ.40.08.00 Опора 58Е-ТВ.42.01.00 Балка передняя 58Е-ТВ.42.02.00 Балка задняя 58Е-ТВ.40.05.00 Кронштейн | C30: =H30/F30 -> 0 | E30: =F30*429 -> 41184 | F30: 96 | G30: =сентябрь!N30 -> 0 | H30: =сентябрь!O30 -> 0 | I30: =E30/F30*J30 -> 0 | N30: =G30+SUM(I30:I36) -> 0 | O30: =H30+SUM(J30:J36) -> 0 | P30: =O30/F30 -> 0 | Q30: =F30-O30 -> 96 | R30: =1-N30/E30 -> 1 | S30: =E30-N30 -> 41184
I31: =E30/F30*J31 -> 0
I32: =E30/F30*J32 -> 0
I33: =E30/F30*J33 -> 0
I34: =E30/F30*J34 -> 0
I35: =E30/F30*J35 -> 0
I36: =E30/F30*J36 -> 0
A37: 1.3. | B37: Элементы: /Пульт оператора 58Е-ТВ.10.20.00, /Бампер 58Е-ТВ.28.110.00 /Ящики задние 58Е-ТВ.28.10.00_58Е-ТВ.28.20.00 /площадка оператора 58Е-ТВ.10.25.00 /кронштейн сидения оператора 58Е-ТВ.28.30.10 /крылья 58Е-ТВ.01.50.00 /колпаки 58Е-ТВ.10.100.00 /стойка 58Е-ТВ.28.40.00 /маслобак 58А-ТВ.12.10.00 /кронштейн транспортного положения стрелы 58Е-ТВ.50.40.74-84 (6 поз.) /кронштейны под элементы гидравлики в поворотной колонне, раме, /Лестница 58Е-ТВ.28.70.00 (боковые ступени) | C37: =H37/F37 -> 0 | E37: =F37*429 -> 71214 | F37: 166 | G37: =сентябрь!N37 -> 0 | H37: =сентябрь!O37 -> 0 | I37: =E37/F37*J37 -> 0 | N37: =G37+SUM(I37:I43) -> 0 | O37: =H37+SUM(J37:J43) -> 0 | P37: =O37/F37 -> 0 | Q37: =F37-O37 -> 166 | R37: =1-N37/E37 -> 1 | S37: =E37-N37 -> 71214
I38: =E37/F37*J38 -> 0
I39: =E37/F37*J39 -> 0
I40: =E37/F37*J40 -> 0
I41: =E37/F37*J41 -> 0
I42: =E37/F37*J42 -> 0
I43: =E37/F37*J43 -> 0
A44: 1.4. | B44: Поворотная колонна 58Е-ТВ.46.01.00: 58Д-ТВ.45.10.20 Кронштейн 58Е-ТВ.46.01.10 Балка 58Е-ТВ.46.10.10 Боковина правая 58Е-ТВ.46.10.10-01 Боковина левая | C44: =H44/F44 -> 0 | D44: =E44/E$177 -> 0.052227343 | E44: =F44*429 -> 29172 | F44: 68 | G44: =сентябрь!N44 -> 0 | H44: =сентябрь!O44 -> 0 | I44: =E44/F44*J44 -> 0 | N44: =G44+SUM(I44:I50) -> 0 | O44: =H44+SUM(J44:J50) -> 0 | P44: =O44/F44 -> 0 | Q44: =F44-O44 -> 68 | R44: =1-N44/E44 -> 1 | S44: =E44-N44 -> 29172
I45: =E44/F44*J45 -> 0
I46: =E44/F44*J46 -> 0
I47: =E44/F44*J47 -> 0
I48: =E44/F44*J48 -> 0
I49: =E44/F44*J49 -> 0
...

Sheet ноябрь
B1: ООО "ПК "Техинком-Центр"
A3: Наряд на оплату труда №_____ от "___" _______________20___г.
F4: Изделие : | H4: =C6 -> ПСС-131.22Э (С42А43) 58Е-ТВ Садко НЕКСТ
B6: Продукция: | C6: =июль!C6 -> ПСС-131.22Э (С42А43) 58Е-ТВ Садко НЕКСТ
B7: Подразделение: высотная техника
B8: Заводской номер: | C8: =июль!C8 -> №011
B9: Количество: | F9: 1 | G9: шт.
B10: Общий фонд по машине | F10: =E177 -> 558558 | G10: руб.
B11: Трудоемкость | F11: =F177 -> 1302 | G11: н/час
B12: Стоимость н/ч (руб) | F12: =E177/F177 -> 429 | G12: руб.
A14: № | B14: Наименование операции | C14: % выполнения операции на начало месяца | D14: Справочно % от суммы наряда | E14: Утвержденные расценки и н/ч | G14: Факт выполнения нарастающим итогом на 01.11.2024 | I14: Факт выполнения за НОЯБРЯ 2024 | K14: Исполнитель (ФИО) | N14: Отработано на 30.11.2024 | P14: % выполнения операции на конец месяца | Q14: Остаток на конец месяца н/ч | R14: Отклонение на конец месяца
A15: п/п | E15: расценка за операцию (руб.) | F15: нормо-час (н/ч) | G15: (руб.) | H15: (н/ч) | I15: Стоимость (руб.) | J15: факт выполнения (н/ч) | K15: з/плата (сделка) | L15: договор ГПХ | M15: подряд | N15: сумма (руб.) | O15: н/ч. | R15: % | S15: рубли
A16: 1 | B16: Сварка-сборка узлов | C16: =H16/F16 -> 0 | D16: =E16/E$177 -> 0.59600614 | E16: =SUM(E23:E92) -> 332904 | F16: =SUM(F23:F92) -> 776 | G16: =SUM(G23:G92) -> 0 | H16: =SUM(H23:H92) -> 0 | I16: =SUM(I23:I92) -> 0 | J16: =SUM(J23:J92) -> 0 | N16: =SUM(N23:N92) -> 0 | O16: =SUM(O23:O92) -> 0 | P16: =O16/F16 -> 0 | Q16: =F16-O16 -> 776 | R16: =1-N16/E16 -> 1 | S16: =E16-N16 -> 332904
A23: 1.1. | B23: Рама опорная 58Е-ТВ.40.00.00-02: 58Е-ТВ.40.01.00 Балка/58Е-ТВ.40.01.00-01 Балка 58Е-ТВ.40.02.00 Балка задних опор 58Е-ТВ.40.03.00-01 Опора 58Б-ТВ.40.12.00 Кронштейн 58Г-ТВ.40.00.40 Кронштейн ручного насоса 58Б-ТВ.00.10.00 Кронштейн 58Б-ТВ.40.12.00 Кронштейн 58Д-ТВ.40.02.10 Кронштейн/58Д-ТВ.40.02.10-01 Кронштейн | C23: =H23/F23 -> 0 | E23: =F23*429 -> 46332 | F23: 108 | G23: =октябрь!N23 -> 0 | H23: =октябрь!O23 -> 0 | I23: =E23/F23*J23 -> 0 | N23: =G23+SUM(I23:I29) -> 0 | O23: =H23+SUM(J23:J29) -> 0 | P23: =O23/F23 -> 0 | Q23: =F23-O23 -> 108 | R23: =1-N23/E23 -> 1 | S23: =E23-N23 -> 46332
I24: =E23/F23*J24 -> 0
I25: =E23/F23*J25 -> 0
I26: =E23/F23*J26 -> 0
I27: =E23/F23*J27 -> 0
I28: =E23/F23*J28 -> 0
I29: =E23/F23*J29 -> 0
A30: 1.2. | B30: Аутригеры 58Е-ТВ.42.00.00: 58Е-ТВ.40.06.00 Кронштейн 58Е-ТВ.40.08.00 Опора 58Е-ТВ.42.01.00 Балка передняя 58Е-ТВ.42.02.00 Балка задняя 58Е-ТВ.40.05.00 Кронштейн | C30: =H30/F30 -> 0 | E30: =F30*429 -> 41184 | F30: 96 | G30: =октябрь!N30 -> 0 | H30: =октябрь!O30 -> 0 | I30: =E30/F30*J30 -> 0 | N30: =G30+SUM(I30:I36) -> 0 | O30: =H30+SUM(J30:J36) -> 0 | P30: =O30/F30 -> 0 | Q30: =F30-O30 -> 96 | R30: =1-N30/E30 -> 1 | S30: =E30-N30 -> 41184
I31: =E30/F30*J31 -> 0
I32: =E30/F30*J32 -> 0
I33: =E30/F30*J33 -> 0
I34: =E30/F30*J34 -> 0
I35: =E30/F30*J35 -> 0
I36: =E30/F30*J36 -> 0
A37: 1.3. | B37: Элементы: /Пульт оператора 58Е-ТВ.10.20.00, /Бампер 58Е-ТВ.28.110.00 /Ящики задние 58Е-ТВ.28.10.00_58Е-ТВ.28.20.00 /площадка оператора 58Е-ТВ.10.25.00 /кронштейн сидения оператора 58Е-ТВ.28.30.10 /крылья 58Е-ТВ.01.50.00 /колпаки 58Е-ТВ.10.100.00 /стойка 58Е-ТВ.28.40.00 /маслобак 58А-ТВ.12.10.00 /кронштейн транспортного положения стрелы 58Е-ТВ.50.40.74-84 (6 поз.) /кронштейны под элементы гидравлики в поворотной колонне, раме, /Лестница 58Е-ТВ.28.70.00 (боковые ступени) | C37: =H37/F37 -> 0 | E37: =F37*429 -> 71214 | F37: 166 | G37: =октябрь!N37 -> 0 | H37: =октябрь!O37 -> 0 | I37: =E37/F37*J37 -> 0 | N37: =G37+SUM(I37:I43) -> 0 | O37: =H37+SUM(J37:J43) -> 0 | P37: =O37/F37 -> 0 | Q37: =F37-O37 -> 166 | R37: =1-N37/E37 -> 1 | S37: =E37-N37 -> 71214
I38: =E37/F37*J38 -> 0
I39: =E37/F37*J39 -> 0
I40: =E37/F37*J40 -> 0
I41: =E37/F37*J41 -> 0
I42: =E37/F37*J42 -> 0
I43: =E37/F37*J43 -> 0
A44: 1.4. | B44: Поворотная колонна 58Е-ТВ.46.01.00: 58Д-ТВ.45.10.20 Кронштейн 58Е-ТВ.46.01.10 Балка 58Е-ТВ.46.10.10 Боковина правая 58Е-ТВ.46.10.10-01 Боковина левая | C44: =H44/F44 -> 0 | D44: =E44/E$177 -> 0.052227343 | E44: =F44*429 -> 29172 | F44: 68 | G44: =октябрь!N44 -> 0 | H44: =октябрь!O44 -> 0 | I44: =E44/F44*J44 -> 0 | N44: =G44+SUM(I44:I50) -> 0 | O44: =H44+SUM(J44:J50) -> 0 | P44: =O44/F44 -> 0 | Q44: =F44-O44 -> 68 | R44: =1-N44/E44 -> 1 | S44: =E44-N44 -> 29172
I45: =E44/F44*J45 -> 0
I46: =E44/F44*J46 -> 0
I47: =E44/F44*J47 -> 0
I48: =E44/F44*J48 -> 0
I49: =E44/F44*J49 -> 0
...

Sheet декабрь
B1: ООО "ПК "Техинком-Центр"
A3: Наряд на оплату труда №_____ от "___" _______________20___г.
F4: Изделие : | H4: =C6 -> ПСС-131.22Э (С42А43) 58Е-ТВ Садко НЕКСТ
B6: Продукция: | C6: =июль!C6 -> ПСС-131.22Э (С42А43) 58Е-ТВ Садко НЕКСТ
B7: Подразделение: высотная техника
B8: Заводской номер: | C8: =июль!C8 -> №011
B9: Количество: | F9: 1 | G9: шт.
B10: Общий фонд по машине | F10: =E177 -> 558558 | G10: руб.
B11: Трудоемкость | F11: =F177 -> 1302 | G11: н/час
B12: Стоимость н/ч (руб) | F12: =E177/F177 -> 429 | G12: руб.
A14: № | B14: Наименование операции | C14: % выполнения операции на начало месяца | D14: Справочно % от суммы наряда | E14: Утвержденные расценки и н/ч | G14: Факт выполнения нарастающим итогом на 01.12.2024 | I14: Факт выполнения за ДЕКАБРЬ 2024 | K14: Исполнитель (ФИО) | N14: Отработано на 31.12.2024 | P14: % выполнения операции на конец месяца | Q14: Остаток на конец месяца н/ч | R14: Отклонение на конец месяца
A15: п/п | E15: расценка за операцию (руб.) | F15: нормо-час (н/ч) | G15: (руб.) | H15: (н/ч) | I15: Стоимость (руб.) | J15: факт выполнения (н/ч) | K15: з/плата (сделка) | L15: договор ГПХ | M15: подряд | N15: сумма (руб.) | O15: н/ч. | R15: % | S15: рубли
A16: 1 | B16: Сварка-сборка узлов | C16: =H16/F16 -> 0 | D16: =E16/E$177 -> 0.59600614 | E16: =SUM(E23:E92) -> 332904 | F16: =SUM(F23:F92) -> 776 | G16: =SUM(G23:G92) -> 0 | H16: =SUM(H23:H92) -> 0 | I16: =SUM(I23:I92) -> 0 | J16: =SUM(J23:J92) -> 0 | N16: =SUM(N23:N92) -> 0 | O16: =SUM(O23:O92) -> 0 | P16: =O16/F16 -> 0 | Q16: =F16-O16 -> 776 | R16: =1-N16/E16 -> 1 | S16: =E16-N16 -> 332904
A23: 1.1. | B23: Рама опорная 58Е-ТВ.40.00.00-02: 58Е-ТВ.40.01.00 Балка/58Е-ТВ.40.01.00-01 Балка 58Е-ТВ.40.02.00 Балка задних опор 58Е-ТВ.40.03.00-01 Опора 58Б-ТВ.40.12.00 Кронштейн 58Г-ТВ.40.00.40 Кронштейн ручного насоса 58Б-ТВ.00.10.00 Кронштейн 58Б-ТВ.40.12.00 Кронштейн 58Д-ТВ.40.02.10 Кронштейн/58Д-ТВ.40.02.10-01 Кронштейн | C23: =H23/F23 -> 0 | E23: =F23*429 -> 46332 | F23: 108 | G23: =ноябрь!N23 -> 0 | H23: =ноябрь!O23 -> 0 | I23: =E23/F23*J23 -> 0 | N23: =G23+SUM(I23:I29) -> 0 | O23: =H23+SUM(J23:J29) -> 0 | P23: =O23/F23 -> 0 | Q23: =F23-O23 -> 108 | R23: =1-N23/E23 -> 1 | S23: =E23-N23 -> 46332
I24: =E23/F23*J24 -> 0
I25: =E23/F23*J25 -> 0
I26: =E23/F23*J26 -> 0
I27: =E23/F23*J27 -> 0
I28: =E23/F23*J28 -> 0
I29: =E23/F23*J29 -> 0
A30: 1.2. | B30: Аутригеры 58Е-ТВ.42.00.00: 58Е-ТВ.40.06.00 Кронштейн 58Е-ТВ.40.08.00 Опора 58Е-ТВ.42.01.00 Балка передняя 58Е-ТВ.42.02.00 Балка задняя 58Е-ТВ.40.05.00 Кронштейн | C30: =H30/F30 -> 0 | E30: =F30*429 -> 41184 | F30: 96 | G30: =ноябрь!N30 -> 0 | H30: =ноябрь!O30 -> 0 | I30: =E30/F30*J30 -> 0 | N30: =G30+SUM(I30:I36) -> 0 | O30: =H30+SUM(J30:J36) -> 0 | P30: =O30/F30 -> 0 | Q30: =F30-O30 -> 96 | R30: =1-N30/E30 -> 1 | S30: =E30-N30 -> 41184
I31: =E30/F30*J31 -> 0
I32: =E30/F30*J32 -> 0
I33: =E30/F30*J33 -> 0
I34: =E30/F30*J34 -> 0
I35: =E30/F30*J35 -> 0
I36: =E30/F30*J36 -> 0
A37: 1.3. | B37: Элементы: /Пульт оператора 58Е-ТВ.10.20.00, /Бампер 58Е-ТВ.28.110.00 /Ящики задние 58Е-ТВ.28.10.00_58Е-ТВ.28.20.00 /площадка оператора 58Е-ТВ.10.25.00 /кронштейн сидения оператора 58Е-ТВ.28.30.10 /крылья 58Е-ТВ.01.50.00 /колпаки 58Е-ТВ.10.100.00 /стойка 58Е-ТВ.28.40.00 /маслобак 58А-ТВ.12.10.00 /кронштейн транспортного положения стрелы 58Е-ТВ.50.40.74-84 (6 поз.) /кронштейны под элементы гидравлики в поворотной колонне, раме, /Лестница 58Е-ТВ.28.70.00 (боковые ступени) | C37: =H37/F37 -> 0 | E37: =F37*429 -> 71214 | F37: 166 | G37: =ноябрь!N37 -> 0 | H37: =ноябрь!O37 -> 0 | I37: =E37/F37*J37 -> 0 | N37: =G37+SUM(I37:I43) -> 0 | O37: =H37+SUM(J37:J43) -> 0 | P37: =O37/F37 -> 0 | Q37: =F37-O37 -> 166 | R37: =1-N37/E37 -> 1 | S37: =E37-N37 -> 71214
I38: =E37/F37*J38 -> 0
I39: =E37/F37*J39 -> 0
I40: =E37/F37*J40 -> 0
I41: =E37/F37*J41 -> 0
I42: =E37/F37*J42 -> 0
I43: =E37/F37*J43 -> 0
A44: 1.4. | B44: Поворотная колонна 58Е-ТВ.46.01.00: 58Д-ТВ.45.10.20 Кронштейн 58Е-ТВ.46.01.10 Балка 58Е-ТВ.46.10.10 Боковина правая 58Е-ТВ.46.10.10-01 Боковина левая | C44: =H44/F44 -> 0 | D44: =E44/E$177 -> 0.052227343 | E44: =F44*429 -> 29172 | F44: 68 | G44: =ноябрь!N44 -> 0 | H44: =ноябрь!O44 -> 0 | I44: =E44/F44*J44 -> 0 | N44: =G44+SUM(I44:I50) -> 0 | O44: =H44+SUM(J44:J50) -> 0 | P44: =O44/F44 -> 0 | Q44: =F44-O44 -> 68 | R44: =1-N44/E44 -> 1 | S44: =E44-N44 -> 29172
I45: =E44/F44*J45 -> 0
I46: =E44/F44*J46 -> 0
I47: =E44/F44*J47 -> 0
I48: =E44/F44*J48 -> 0
I49: =E44/F44*J49 -> 0
...
